
2018-05-23 19:39:03:---[request]---:<QueryDict: {}>
2018-05-23 19:39:03:---[InterfaceAttr insert fail]---:Traceback (most recent call last):
  File "D:\Users\huangmin\AppData\Roaming\Python\Python36\site-packages\django\db\backends\utils.py", line 85, in _execute
    return self.cursor.execute(sql, params)
  File "D:\Users\huangmin\AppData\Roaming\Python\Python36\site-packages\django\db\backends\mysql\base.py", line 71, in execute
    return self.cursor.execute(query, args)
  File "D:\SOFTWARE\python\lib\site-packages\pymysql\cursors.py", line 165, in execute
    result = self._query(query)
  File "D:\SOFTWARE\python\lib\site-packages\pymysql\cursors.py", line 321, in _query
    conn.query(q)
  File "D:\SOFTWARE\python\lib\site-packages\pymysql\connections.py", line 860, in query
    self._affected_rows = self._read_query_result(unbuffered=unbuffered)
  File "D:\SOFTWARE\python\lib\site-packages\pymysql\connections.py", line 1061, in _read_query_result
    result.read()
  File "D:\SOFTWARE\python\lib\site-packages\pymysql\connections.py", line 1349, in read
    first_packet = self.connection._read_packet()
  File "D:\SOFTWARE\python\lib\site-packages\pymysql\connections.py", line 1018, in _read_packet
    packet.check_error()
  File "D:\SOFTWARE\python\lib\site-packages\pymysql\connections.py", line 384, in check_error
    err.raise_mysql_exception(self._data)
  File "D:\SOFTWARE\python\lib\site-packages\pymysql\err.py", line 107, in raise_mysql_exception
    raise errorclass(errno, errval)
pymysql.err.IntegrityError: (1048, "Column 'type' cannot be null")

The above exception was the direct cause of the following exception:

Traceback (most recent call last):
  File "d:\Users\huangmin\git\interface_control\interface.py", line 205, in interface_attr
    InterfaceAttr.objects.create(field = field_name,max = field_max,min = field_min,type = field_type,is_null = field_null,interface_id = id,memo = memo)
  File "D:\Users\huangmin\AppData\Roaming\Python\Python36\site-packages\django\db\models\manager.py", line 82, in manager_method
    return getattr(self.get_queryset(), name)(*args, **kwargs)
  File "D:\Users\huangmin\AppData\Roaming\Python\Python36\site-packages\django\db\models\query.py", line 417, in create
    obj.save(force_insert=True, using=self.db)
  File "D:\Users\huangmin\AppData\Roaming\Python\Python36\site-packages\django\db\models\base.py", line 729, in save
    force_update=force_update, update_fields=update_fields)
  File "D:\Users\huangmin\AppData\Roaming\Python\Python36\site-packages\django\db\models\base.py", line 759, in save_base
    updated = self._save_table(raw, cls, force_insert, force_update, using, update_fields)
  File "D:\Users\huangmin\AppData\Roaming\Python\Python36\site-packages\django\db\models\base.py", line 842, in _save_table
    result = self._do_insert(cls._base_manager, using, fields, update_pk, raw)
  File "D:\Users\huangmin\AppData\Roaming\Python\Python36\site-packages\django\db\models\base.py", line 880, in _do_insert
    using=using, raw=raw)
  File "D:\Users\huangmin\AppData\Roaming\Python\Python36\site-packages\django\db\models\manager.py", line 82, in manager_method
    return getattr(self.get_queryset(), name)(*args, **kwargs)
  File "D:\Users\huangmin\AppData\Roaming\Python\Python36\site-packages\django\db\models\query.py", line 1125, in _insert
    return query.get_compiler(using=using).execute_sql(return_id)
  File "D:\Users\huangmin\AppData\Roaming\Python\Python36\site-packages\django\db\models\sql\compiler.py", line 1284, in execute_sql
    cursor.execute(sql, params)
  File "D:\Users\huangmin\AppData\Roaming\Python\Python36\site-packages\django\db\backends\utils.py", line 100, in execute
    return super().execute(sql, params)
  File "D:\Users\huangmin\AppData\Roaming\Python\Python36\site-packages\django\db\backends\utils.py", line 68, in execute
    return self._execute_with_wrappers(sql, params, many=False, executor=self._execute)
  File "D:\Users\huangmin\AppData\Roaming\Python\Python36\site-packages\django\db\backends\utils.py", line 77, in _execute_with_wrappers
    return executor(sql, params, many, context)
  File "D:\Users\huangmin\AppData\Roaming\Python\Python36\site-packages\django\db\backends\utils.py", line 85, in _execute
    return self.cursor.execute(sql, params)
  File "D:\Users\huangmin\AppData\Roaming\Python\Python36\site-packages\django\db\utils.py", line 89, in __exit__
    raise dj_exc_value.with_traceback(traceback) from exc_value
  File "D:\Users\huangmin\AppData\Roaming\Python\Python36\site-packages\django\db\backends\utils.py", line 85, in _execute
    return self.cursor.execute(sql, params)
  File "D:\Users\huangmin\AppData\Roaming\Python\Python36\site-packages\django\db\backends\mysql\base.py", line 71, in execute
    return self.cursor.execute(query, args)
  File "D:\SOFTWARE\python\lib\site-packages\pymysql\cursors.py", line 165, in execute
    result = self._query(query)
  File "D:\SOFTWARE\python\lib\site-packages\pymysql\cursors.py", line 321, in _query
    conn.query(q)
  File "D:\SOFTWARE\python\lib\site-packages\pymysql\connections.py", line 860, in query
    self._affected_rows = self._read_query_result(unbuffered=unbuffered)
  File "D:\SOFTWARE\python\lib\site-packages\pymysql\connections.py", line 1061, in _read_query_result
    result.read()
  File "D:\SOFTWARE\python\lib\site-packages\pymysql\connections.py", line 1349, in read
    first_packet = self.connection._read_packet()
  File "D:\SOFTWARE\python\lib\site-packages\pymysql\connections.py", line 1018, in _read_packet
    packet.check_error()
  File "D:\SOFTWARE\python\lib\site-packages\pymysql\connections.py", line 384, in check_error
    err.raise_mysql_exception(self._data)
  File "D:\SOFTWARE\python\lib\site-packages\pymysql\err.py", line 107, in raise_mysql_exception
    raise errorclass(errno, errval)
django.db.utils.IntegrityError: (1048, "Column 'type' cannot be null")

2018-05-23 20:57:35:---[request]---:<QueryDict: {}>
2018-05-23 20:57:35:---[InterfaceAttr insert fail]---:Traceback (most recent call last):
  File "D:\Users\huangmin\AppData\Roaming\Python\Python36\site-packages\django\db\backends\utils.py", line 85, in _execute
    return self.cursor.execute(sql, params)
  File "D:\Users\huangmin\AppData\Roaming\Python\Python36\site-packages\django\db\backends\mysql\base.py", line 71, in execute
    return self.cursor.execute(query, args)
  File "D:\SOFTWARE\python\lib\site-packages\pymysql\cursors.py", line 165, in execute
    result = self._query(query)
  File "D:\SOFTWARE\python\lib\site-packages\pymysql\cursors.py", line 321, in _query
    conn.query(q)
  File "D:\SOFTWARE\python\lib\site-packages\pymysql\connections.py", line 860, in query
    self._affected_rows = self._read_query_result(unbuffered=unbuffered)
  File "D:\SOFTWARE\python\lib\site-packages\pymysql\connections.py", line 1061, in _read_query_result
    result.read()
  File "D:\SOFTWARE\python\lib\site-packages\pymysql\connections.py", line 1349, in read
    first_packet = self.connection._read_packet()
  File "D:\SOFTWARE\python\lib\site-packages\pymysql\connections.py", line 1018, in _read_packet
    packet.check_error()
  File "D:\SOFTWARE\python\lib\site-packages\pymysql\connections.py", line 384, in check_error
    err.raise_mysql_exception(self._data)
  File "D:\SOFTWARE\python\lib\site-packages\pymysql\err.py", line 107, in raise_mysql_exception
    raise errorclass(errno, errval)
pymysql.err.IntegrityError: (1048, "Column 'type' cannot be null")

The above exception was the direct cause of the following exception:

Traceback (most recent call last):
  File "d:\Users\huangmin\git\interface_control\interface.py", line 205, in interface_attr
    InterfaceAttr.objects.create(field = field_name,max = field_max,min = field_min,type = field_type,is_null = field_null,interface_id = id,memo = memo)
  File "D:\Users\huangmin\AppData\Roaming\Python\Python36\site-packages\django\db\models\manager.py", line 82, in manager_method
    return getattr(self.get_queryset(), name)(*args, **kwargs)
  File "D:\Users\huangmin\AppData\Roaming\Python\Python36\site-packages\django\db\models\query.py", line 417, in create
    obj.save(force_insert=True, using=self.db)
  File "D:\Users\huangmin\AppData\Roaming\Python\Python36\site-packages\django\db\models\base.py", line 729, in save
    force_update=force_update, update_fields=update_fields)
  File "D:\Users\huangmin\AppData\Roaming\Python\Python36\site-packages\django\db\models\base.py", line 759, in save_base
    updated = self._save_table(raw, cls, force_insert, force_update, using, update_fields)
  File "D:\Users\huangmin\AppData\Roaming\Python\Python36\site-packages\django\db\models\base.py", line 842, in _save_table
    result = self._do_insert(cls._base_manager, using, fields, update_pk, raw)
  File "D:\Users\huangmin\AppData\Roaming\Python\Python36\site-packages\django\db\models\base.py", line 880, in _do_insert
    using=using, raw=raw)
  File "D:\Users\huangmin\AppData\Roaming\Python\Python36\site-packages\django\db\models\manager.py", line 82, in manager_method
    return getattr(self.get_queryset(), name)(*args, **kwargs)
  File "D:\Users\huangmin\AppData\Roaming\Python\Python36\site-packages\django\db\models\query.py", line 1125, in _insert
    return query.get_compiler(using=using).execute_sql(return_id)
  File "D:\Users\huangmin\AppData\Roaming\Python\Python36\site-packages\django\db\models\sql\compiler.py", line 1284, in execute_sql
    cursor.execute(sql, params)
  File "D:\Users\huangmin\AppData\Roaming\Python\Python36\site-packages\django\db\backends\utils.py", line 100, in execute
    return super().execute(sql, params)
  File "D:\Users\huangmin\AppData\Roaming\Python\Python36\site-packages\django\db\backends\utils.py", line 68, in execute
    return self._execute_with_wrappers(sql, params, many=False, executor=self._execute)
  File "D:\Users\huangmin\AppData\Roaming\Python\Python36\site-packages\django\db\backends\utils.py", line 77, in _execute_with_wrappers
    return executor(sql, params, many, context)
  File "D:\Users\huangmin\AppData\Roaming\Python\Python36\site-packages\django\db\backends\utils.py", line 85, in _execute
    return self.cursor.execute(sql, params)
  File "D:\Users\huangmin\AppData\Roaming\Python\Python36\site-packages\django\db\utils.py", line 89, in __exit__
    raise dj_exc_value.with_traceback(traceback) from exc_value
  File "D:\Users\huangmin\AppData\Roaming\Python\Python36\site-packages\django\db\backends\utils.py", line 85, in _execute
    return self.cursor.execute(sql, params)
  File "D:\Users\huangmin\AppData\Roaming\Python\Python36\site-packages\django\db\backends\mysql\base.py", line 71, in execute
    return self.cursor.execute(query, args)
  File "D:\SOFTWARE\python\lib\site-packages\pymysql\cursors.py", line 165, in execute
    result = self._query(query)
  File "D:\SOFTWARE\python\lib\site-packages\pymysql\cursors.py", line 321, in _query
    conn.query(q)
  File "D:\SOFTWARE\python\lib\site-packages\pymysql\connections.py", line 860, in query
    self._affected_rows = self._read_query_result(unbuffered=unbuffered)
  File "D:\SOFTWARE\python\lib\site-packages\pymysql\connections.py", line 1061, in _read_query_result
    result.read()
  File "D:\SOFTWARE\python\lib\site-packages\pymysql\connections.py", line 1349, in read
    first_packet = self.connection._read_packet()
  File "D:\SOFTWARE\python\lib\site-packages\pymysql\connections.py", line 1018, in _read_packet
    packet.check_error()
  File "D:\SOFTWARE\python\lib\site-packages\pymysql\connections.py", line 384, in check_error
    err.raise_mysql_exception(self._data)
  File "D:\SOFTWARE\python\lib\site-packages\pymysql\err.py", line 107, in raise_mysql_exception
    raise errorclass(errno, errval)
django.db.utils.IntegrityError: (1048, "Column 'type' cannot be null")
